Workbook

Sheet Entrada
B3: Critérios | D3: Análise Pareada (atribua notas entre 1 e 9) | N3: Concorrentes | P3: Notas para cada concorrente | R3: Entre 1 e 9
A4: 1 | B4: Preço | D4: =B4 -> Preço | I4: =B5 -> Durabilidade | N4: arno | P4: =N4 -> arno | Q4: =B4 -> Preço | R4: 6
A5: 2 | B5: Durabilidade | D5: 4 | N5: wallita | Q5: =B5 -> Durabilidade | R5: 7
A6: 3 | B6: Cor | N6: black | Q6: =B6 -> Cor | R6: 3
A7: 4 | B7: Acabamento | D7: =B4 -> Preço | I7: =B6 -> Cor | N7: singer | Q7: =B7 -> Acabamento | R7: 2
A8: 5 | B8: Design | D8: 2 | N8: Mondial | Q8: =B8 -> Design | R8: 2
A9: 6 | B9: Garantia | Q9: =B9 -> Garantia | R9: 3
A10: 7 | B10: Peso | D10: =B4 -> Preço | I10: =B7 -> Acabamento | Q10: =B10 -> Peso | R10: 4
I11: 2 | P11: =N5 -> wallita | Q11: =Q4 -> Preço | R11: 4
Q12: =Q5 -> Durabilidade | R12: 6
D13: =B4 -> Preço | I13: =B8 -> Design | Q13: =Q6 -> Cor | R13: 4
D14: 4 | Q14: =Q7 -> Acabamento | R14: 9
Q15: =Q8 -> Design | R15: 7
D16: =B4 -> Preço | I16: =B9 -> Garantia | Q16: =Q9 -> Garantia | R16: 5
D17: 3 | Q17: =Q10 -> Peso | R17: 1
P18: =N6 -> black | Q18: =Q4 -> Preço | R18: 2
D19: =B4 -> Preço | I19: =B10 -> Peso | Q19: =Q5 -> Durabilidade | R19: 3
D20: 7 | Q20: =Q6 -> Cor | R20: 8
Q21: =Q7 -> Acabamento | R21: 9
D22: =B5 -> Durabilidade | I22: =B6 -> Cor | Q22: =Q8 -> Design | R22: 7
D23: 3 | Q23: =Q9 -> Garantia | R23: 3
Q24: =Q10 -> Peso | R24: 2
D25: =B5 -> Durabilidade | I25: =B7 -> Acabamento | P25: =N7 -> singer | Q25: =Q4 -> Preço | R25: 4
D26: 1 | Q26: =Q5 -> Durabilidade | R26: 3
Q27: =Q6 -> Cor | R27: 2
D28: =B5 -> Durabilidade | I28: =B8 -> Design | Q28: =Q7 -> Acabamento | R28: 3
I29: 2 | Q29: =Q8 -> Design | R29: 7
Q30: =Q9 -> Garantia | R30: 8
D31: =B5 -> Durabilidade | I31: =B9 -> Garantia | Q31: =Q10 -> Peso | R31: 6
I32: 2 | P32: =N8 -> Mondial | Q32: =Q4 -> Preço | R32: 1
Q33: =Q5 -> Durabilidade | R33: 2
D34: =B5 -> Durabilidade | I34: =B10 -> Peso | Q34: =Q6 -> Cor | R34: 4
D35: 5 | Q35: =Q7 -> Acabamento | R35: 1
Q36: =Q8 -> Design | R36: 7
D37: =B6 -> Cor | I37: =B7 -> Acabamento | Q37: =Q9 -> Garantia | R37: 9
I38: 2 | Q38: =Q10 -> Peso | R38: 4
D40: =B6 -> Cor | I40: =B8 -> Design
I41: 1
D43: =B6 -> Cor | I43: =B9 -> Garantia
I44: 2
...

Sheet calc Hier
B2: Critérios | C2: {=TRANSPOSE(B3:B9)} -> Preço | D2: Durabilidade | E2: Cor | F2: Acabamento | G2: Design | H2: Garantia | I2: Peso
B3: =Entrada!B4 -> Preço | C3: 1 | D3: =IF(Entrada!D5>0,Entrada!D5,1/Entrada!I5) -> 4 | E3: =IF(Entrada!D8>0,Entrada!D8,1/Entrada!I8) -> 2 | F3: =IF(Entrada!D11>0,Entrada!D11,1/Entrada!I11) -> 0.5 | G3: =IF(Entrada!D14>0,Entrada!D14,1/Entrada!I14) -> 4 | H3: =IF(Entrada!D17>0,Entrada!D17,1/Entrada!I17) -> 3 | I3: =IF(Entrada!D20>0,Entrada!D20,1/Entrada!I20) -> 7
B4: =Entrada!B5 -> Durabilidade | C4: =1/D3 -> 0.25 | D4: 1 | E4: =IF(Entrada!D23>0,Entrada!D23,1/Entrada!I23) -> 3 | F4: =IF(Entrada!D26>0,Entrada!D26,1/Entrada!I26) -> 1 | G4: =IF(Entrada!D29>0,Entrada!D29,1/Entrada!I29) -> 0.5 | H4: =IF(Entrada!D32>0,Entrada!D32,1/Entrada!I32) -> 0.5 | I4: =IF(Entrada!D35>0,Entrada!D35,1/Entrada!I35) -> 5
B5: =Entrada!B6 -> Cor | C5: =1/E3 -> 0.5 | D5: =1/E4 -> 0.33333333 | E5: 1 | F5: =IF(Entrada!D38>0,Entrada!D38,1/Entrada!I38) -> 0.5 | G5: =IF(Entrada!D41>0,Entrada!D41,1/Entrada!I41) -> 1 | H5: =IF(Entrada!D44>0,Entrada!D44,1/Entrada!I44) -> 0.5 | I5: =IF(Entrada!D47>0,Entrada!D47,1/Entrada!I47) -> 2
B6: =Entrada!B7 -> Acabamento | C6: =1/F3 -> 2 | D6: =1/F4 -> 1 | E6: =1/F5 -> 2 | F6: 1 | G6: =IF(Entrada!D50>0,Entrada!D50,1/Entrada!I50) -> 0.25 | H6: =IF(Entrada!D53>0,Entrada!D53,1/Entrada!I53) -> 1 | I6: =IF(Entrada!D56>0,Entrada!D56,1/Entrada!I56) -> 3
B7: =Entrada!B8 -> Design | C7: =1/G3 -> 0.25 | D7: =1/G4 -> 2 | E7: =1/G5 -> 1 | F7: =1/G6 -> 4 | G7: 1 | H7: =IF(Entrada!D59>0,Entrada!D59,1/Entrada!I59) -> 2 | I7: =IF(Entrada!D62>0,Entrada!D62,1/Entrada!I62) -> 1
B8: =Entrada!B9 -> Garantia | C8: =1/H3 -> 0.33333333 | D8: =1/H4 -> 2 | E8: =1/H5 -> 2 | F8: =1/H6 -> 1 | G8: =1/H7 -> 0.5 | H8: 1 | I8: =IF(Entrada!D65>0,Entrada!D65,1/Entrada!I65) -> 3
B9: =Entrada!B10 -> Peso | C9: =1/I3 -> 0.14285714 | D9: =1/I4 -> 0.2 | E9: =1/I5 -> 0.5 | F9: =1/I6 -> 0.33333333 | G9: =1/I7 -> 1 | H9: =1/I8 -> 0.33333333 | I9: 1
B10: Soma | C10: =SUM(C3:C9) -> 4.4761905 | D10: =SUM(D3:D9) -> 10.533333 | E10: =SUM(E3:E9) -> 11.5 | F10: =SUM(F3:F9) -> 8.3333333 | G10: =SUM(G3:G9) -> 8.25 | H10: =SUM(H3:H9) -> 8.3333333 | I10: =SUM(I3:I9) -> 22 | J10: Peso do critério
B11: =Entrada!B4 -> Preço | C11: =C3/$C$10 -> 0.22340426 | D11: =D3/$D$10 -> 0.37974684 | E11: =E3/$E$10 -> 0.17391304 | F11: =F3/$F$10 -> 0.06 | G11: =G3/$G$10 -> 0.48484848 | H11: =H3/$H$10 -> 0.36 | I11: =I3/$I$10 -> 0.31818182 | J11: =AVERAGE(C11:I11) -> 0.28572778
B12: =Entrada!B5 -> Durabilidade | C12: =C4/$C$10 -> 0.055851064 | D12: =D4/$D$10 -> 0.094936709 | E12: =E4/$E$10 -> 0.26086957 | F12: =F4/$F$10 -> 0.12 | G12: =G4/$G$10 -> 0.060606061 | H12: =H4/$H$10 -> 0.06 | I12: =I4/$I$10 -> 0.22727273 | J12: =AVERAGE(C12:I12) -> 0.12564802
B13: =Entrada!B6 -> Cor | C13: =C5/$C$10 -> 0.11170213 | D13: =D5/$D$10 -> 0.03164557 | E13: =E5/$E$10 -> 0.086956522 | F13: =F5/$F$10 -> 0.06 | G13: =G5/$G$10 -> 0.12121212 | H13: =H5/$H$10 -> 0.06 | I13: =I5/$I$10 -> 0.090909091 | J13: =AVERAGE(C13:I13) -> 0.08034649
B14: =Entrada!B7 -> Acabamento | C14: =C6/$C$10 -> 0.44680851 | D14: =D6/$D$10 -> 0.094936709 | E14: =E6/$E$10 -> 0.17391304 | F14: =F6/$F$10 -> 0.12 | G14: =G6/$G$10 -> 0.03030303 | H14: =H6/$H$10 -> 0.12 | I14: =I6/$I$10 -> 0.13636364 | J14: =AVERAGE(C14:I14) -> 0.16033213
B15: =Entrada!B8 -> Design | C15: =C7/$C$10 -> 0.055851064 | D15: =D7/$D$10 -> 0.18987342 | E15: =E7/$E$10 -> 0.086956522 | F15: =F7/$F$10 -> 0.48 | G15: =G7/$G$10 -> 0.12121212 | H15: =H7/$H$10 -> 0.24 | I15: =I7/$I$10 -> 0.045454545 | J15: =AVERAGE(C15:I15) -> 0.17419252
B16: =Entrada!B9 -> Garantia | C16: =C8/$C$10 -> 0.074468085 | D16: =D8/$D$10 -> 0.18987342 | E16: =E8/$E$10 -> 0.17391304 | F16: =F8/$F$10 -> 0.12 | G16: =G8/$G$10 -> 0.060606061 | H16: =H8/$H$10 -> 0.12 | I16: =I8/$I$10 -> 0.13636364 | J16: =AVERAGE(C16:I16) -> 0.12503203
B17: =Entrada!B10 -> Peso | C17: =C9/$C$10 -> 0.031914894 | D17: =D9/$D$10 -> 0.018987342 | E17: =E9/$E$10 -> 0.043478261 | F17: =F9/$F$10 -> 0.04 | G17: =G9/$G$10 -> 0.12121212 | H17: =H9/$H$10 -> 0.04 | I17: =I9/$I$10 -> 0.045454545 | J17: =AVERAGE(C17:I17) -> 0.048721023
B20: Critérios | C20: =C2 -> Preço | D20: =D2 -> Durabilidade | E20: =E2 -> Cor | F20: =F2 -> Acabamento | G20: =G2 -> Design | H20: =H2 -> Garantia | I20: =I2 -> Peso | J20: soma | K20: Peso do critério | L20: Soma/Peso
B21: Preço | C21: =C3*$J$11 -> 0.28572778 | D21: =D3*$J$12 -> 0.50259207 | E21: =E3*$J$13 -> 0.16069298 | F21: =F3*$J$14 -> 0.080166066 | G21: =G3*$J$15 -> 0.6967701 | H21: =H3*$J$16 -> 0.3750961 | I21: =I3*$J$17 -> 0.34104716 | J21: =SUM(C21:I21) -> 2.4420923 | K21: =J11 -> 0.28572778 | L21: =J21/K21 -> 8.5469193
B22: Design | C22: =C4*$J$11 -> 0.071431944 | D22: =D4*$J$12 -> 0.12564802 | E22: =E4*$J$13 -> 0.24103947 | F22: =F4*$J$14 -> 0.16033213 | G22: =G4*$J$15 -> 0.087096262 | H22: =H4*$J$16 -> 0.062516017 | I22: =I4*$J$17 -> 0.24360512 | J22: =SUM(C22:I22) -> 0.99166896 | K22: =J12 -> 0.12564802 | L22: =J22/K22 -> 7.8924362
B23: Cor | C23: =C5*$J$11 -> 0.14286389 | D23: =D5*$J$12 -> 0.041882673 | E23: =E5*$J$13 -> 0.08034649 | F23: =F5*$J$14 -> 0.080166066 | G23: =G5*$J$15 -> 0.17419252 | H23: =H5*$J$16 -> 0.062516017 | I23: =I5*$J$17 -> 0.097442047 | J23: =SUM(C23:I23) -> 0.67940971 | K23: =J13 -> 0.08034649 | L23: =J23/K23 -> 8.4559973
B24: Embalagem | C24: =C6*$J$11 -> 0.57145555 | D24: =D6*$J$12 -> 0.12564802 | E24: =E6*$J$13 -> 0.16069298 | F24: =F6*$J$14 -> 0.16033213 | G24: =G6*$J$15 -> 0.043548131 | H24: =H6*$J$16 -> 0.12503203 | I24: =I6*$J$17 -> 0.14616307 | J24: =SUM(C24:I24) -> 1.3328719 | K24: =J14 -> 0.16033213 | L24: =J24/K24 -> 8.3131927
B25: Bico | C25: =C7*$J$11 -> 0.071431944 | D25: =D7*$J$12 -> 0.25129604 | E25: =E7*$J$13 -> 0.08034649 | F25: =F7*$J$14 -> 0.64132853 | G25: =G7*$J$15 -> 0.17419252 | H25: =H7*$J$16 -> 0.25006407 | I25: =I7*$J$17 -> 0.048721023 | J25: =SUM(C25:I25) -> 1.5173806 | K25: =J15 -> 0.17419252 | L25: =J25/K25 -> 8.7109399
B26: Anti-cólica | C26: =C8*$J$11 -> 0.095242592 | D26: =D8*$J$12 -> 0.25129604 | E26: =E8*$J$13 -> 0.16069298 | F26: =F8*$J$14 -> 0.16033213 | G26: =G8*$J$15 -> 0.087096262 | H26: =H8*$J$16 -> 0.12503203 | I26: =I8*$J$17 -> 0.14616307 | J26: =SUM(C26:I26) -> 1.0258551 | K26: =J16 -> 0.12503203 | L26: =J26/K26 -> 8.2047382
B27: Vendedor | C27: =C9*$J$11 -> 0.040818254 | D27: =D9*$J$12 -> 0.025129604 | E27: =E9*$J$13 -> 0.040173245 | F27: =F9*$J$14 -> 0.053444044 | G27: =G9*$J$15 -> 0.17419252 | H27: =H9*$J$16 -> 0.041677345 | I27: =I9*$J$17 -> 0.048721023 | J27: =SUM(C27:I27) -> 0.42415604 | K27: =J17 -> 0.048721023 | L27: =J27/K27 -> 8.7058114
K29: Lâmbda Max | L29: =(L21+L22+L23+L24+L25+L26+L27)/7 -> 8.4042907
K30: CI | L30: =(L29-7)/6 -> 0.23404845
K31: CR (CI/RI) | L31: =L30/1.32 -> 0.17730943

Sheet Mapas de posicionamento
B1: Tamanho da bola | C1: 1 | D1: 1 | E1: 1 | F1: 1 | G1: 1 | I1: Critério 1 | J1: X | K1: Critério 2 | L1: Fator de Impacto
C2: =Entrada!N4 -> arno | D2: =Entrada!N5 -> wallita | E2: =Entrada!N6 -> black | F2: =Entrada!N7 -> singer | G2: =Entrada!N8 -> Mondial | I2: Preço | J2: X | K2: Design | L2: ='calc Hier'!J11*'calc Hier'!J12 -> 0.035901129
B3: =Entrada!B4 -> Preço | C3: =Entrada!R4 -> 6 | D3: =Entrada!R11 -> 4 | E3: =Entrada!R18 -> 2 | F3: =Entrada!R25 -> 4 | G3: =Entrada!R32 -> 1 | I3: Preço | J3: X | K3: Acabamento | L3: ='calc Hier'!J11*'calc Hier'!J13 -> 0.022957224
B4: =Entrada!B5 -> Durabilidade | C4: =Entrada!R5 -> 7 | D4: =Entrada!R12 -> 6 | E4: =Entrada!R19 -> 3 | F4: =Entrada!R26 -> 3 | G4: =Entrada!R33 -> 2 | I4: Preço | J4: X | K4: Motorização | L4: ='calc Hier'!J11*'calc Hier'!J14 -> 0.045811344
B5: =Entrada!B6 -> Cor | C5: =Entrada!R6 -> 3 | D5: =Entrada!R13 -> 4 | E5: =Entrada!R20 -> 8 | F5: =Entrada!R27 -> 2 | G5: =Entrada!R34 -> 4 | I5: Preço | J5: X | K5: Estabilidade | L5: ='calc Hier'!J11*'calc Hier'!J15 -> 0.049771643
B6: =Entrada!B7 -> Acabamento | C6: =Entrada!R7 -> 2 | D6: =Entrada!R14 -> 9 | E6: =Entrada!R21 -> 9 | F6: =Entrada!R28 -> 3 | G6: =Entrada!R35 -> 1 | I6: Preço | J6: X | K6: Serviço | L6: ='calc Hier'!J11*'calc Hier'!J16 -> 0.035725125
B7: =Entrada!B8 -> Design | C7: =Entrada!R8 -> 2 | D7: =Entrada!R15 -> 7 | E7: =Entrada!R22 -> 7 | F7: =Entrada!R29 -> 7 | G7: =Entrada!R36 -> 7 | I7: Preço | J7: X | K7: pós-venda | L7: ='calc Hier'!J11*'calc Hier'!J17 -> 0.01392095
B8: =Entrada!B9 -> Garantia | C8: =Entrada!R9 -> 3 | D8: =Entrada!R16 -> 5 | E8: =Entrada!R23 -> 3 | F8: =Entrada!R30 -> 8 | G8: =Entrada!R37 -> 9 | I8: Design | J8: X | K8: Acabamento | L8: ='calc Hier'!J12*'calc Hier'!J13 -> 0.010095377
B9: =Entrada!B10 -> Peso | C9: =Entrada!R10 -> 4 | D9: =Entrada!R17 -> 1 | E9: =Entrada!R24 -> 2 | F9: =Entrada!R31 -> 6 | G9: =Entrada!R38 -> 4 | I9: Design | J9: X | K9: Motorização | L9: ='calc Hier'!J12*'calc Hier'!J14 -> 0.020145415
I10: Design | J10: X | K10: Estabilidade | L10: ='calc Hier'!J12*'calc Hier'!J15 -> 0.021886945
I11: Design | J11: X | K11: Serviço | L11: ='calc Hier'!J12*'calc Hier'!J16 -> 0.015710027
I12: Design | J12: X | K12: pós-venda | L12: ='calc Hier'!J12*'calc Hier'!J17 -> 0.0061217
I13: Acabamento | J13: X | K13: Motorização | L13: ='calc Hier'!$J$13*'calc Hier'!J14 -> 0.012882124
I14: Acabamento | J14: X | K14: Estabilidade | L14: ='calc Hier'!$J$13*'calc Hier'!J15 -> 0.013995758
I15: Acabamento | J15: X | K15: Serviço | L15: ='calc Hier'!$J$13*'calc Hier'!J16 -> 0.010045885
I16: Acabamento | J16: X | K16: pós-venda | L16: ='calc Hier'!$J$13*'calc Hier'!J17 -> 0.0039145632
I17: Motorização | J17: X | K17: Estabilidade | L17: ='calc Hier'!$J$14*'calc Hier'!J15 -> 0.027928659
I18: Motorização | J18: X | K18: Serviço | L18: ='calc Hier'!$J$14*'calc Hier'!J16 -> 0.020046653
I19: Motorização | J19: X | K19: pós-venda | L19: ='calc Hier'!$J$14*'calc Hier'!J17 -> 0.0078115456
I20: Estabilidade | J20: X | K20: Serviço | L20: ='calc Hier'!J15*'calc Hier'!J16 -> 0.021779646
I21: Estabilidade | J21: X | K21: pós-venda | L21: ='calc Hier'!J15*'calc Hier'!J17 -> 0.008486838
I22: Serviço | J22: X | K22: pós-venda | L22: ='calc Hier'!J16*'calc Hier'!J17 -> 0.0060916887

Sheet Radar
C2: Satisfação | H2: Oportunidade
A3: Item a ser avaliado | B3: Importância | C3: ='Mapas de posicionamento'!C2 -> arno | D3: ='Mapas de posicionamento'!D2 -> wallita | E3: ='Mapas de posicionamento'!E2 -> black | F3: ='Mapas de posicionamento'!F2 -> singer | G3: ='Mapas de posicionamento'!G2 -> Mondial | H3: =C3 -> arno | I3: =D3 -> wallita | J3: =E3 -> black | K3: =F3 -> singer | L3: =G3 -> Mondial
A4: ='Mapas de posicionamento'!B3 -> Preço | B4: =C14 -> 9 | C4: ='Mapas de posicionamento'!C3 -> 6 | D4: ='Mapas de posicionamento'!D3 -> 4 | E4: ='Mapas de posicionamento'!E3 -> 2 | F4: ='Mapas de posicionamento'!F3 -> 4 | G4: ='Mapas de posicionamento'!G3 -> 1 | H4: =$B4+($B4-C4) -> 12 | I4: =$B4+($B4-D4) -> 14 | J4: =$B4+($B4-E4) -> 16 | K4: =$B4+($B4-F4) -> 14 | L4: =$B4+($B4-G4) -> 17
A5: ='Mapas de posicionamento'!B4 -> Durabilidade | B5: =C15 -> 3.9577257 | C5: ='Mapas de posicionamento'!C4 -> 7 | D5: ='Mapas de posicionamento'!D4 -> 6 | E5: ='Mapas de posicionamento'!E4 -> 3 | F5: ='Mapas de posicionamento'!F4 -> 3 | G5: ='Mapas de posicionamento'!G4 -> 2 | H5: =B5+(B5-C5) -> 0.91545138 | I5: =$B5+($B5-D5) -> 1.9154514 | J5: =$B5+($B5-E5) -> 4.9154514 | K5: =$B5+($B5-F5) -> 4.9154514 | L5: =$B5+($B5-G5) -> 5.9154514
A6: ='Mapas de posicionamento'!B5 -> Cor | B6: =C16 -> 2.5307949 | C6: ='Mapas de posicionamento'!C5 -> 3 | D6: ='Mapas de posicionamento'!D5 -> 4 | E6: ='Mapas de posicionamento'!E5 -> 8 | F6: ='Mapas de posicionamento'!F5 -> 2 | G6: ='Mapas de posicionamento'!G5 -> 4 | H6: =B6+(B6-C6) -> 2.0615899 | I6: =$B6+($B6-D6) -> 1.0615899 | J6: =$B6+($B6-E6) -> -2.9384101 | K6: =$B6+($B6-F6) -> 3.0615899 | L6: =$B6+($B6-G6) -> 1.0615899
A7: ='Mapas de posicionamento'!B6 -> Acabamento | B7: =C17 -> 5.0502237 | C7: ='Mapas de posicionamento'!C6 -> 2 | D7: ='Mapas de posicionamento'!D6 -> 9 | E7: ='Mapas de posicionamento'!E6 -> 9 | F7: ='Mapas de posicionamento'!F6 -> 3 | G7: ='Mapas de posicionamento'!G6 -> 1 | H7: =B7+(B7-C7) -> 8.1004474 | I7: =$B7+($B7-D7) -> 1.1004474 | J7: =$B7+($B7-E7) -> 1.1004474 | K7: =$B7+($B7-F7) -> 7.1004474 | L7: =$B7+($B7-G7) -> 9.1004474
A8: ='Mapas de posicionamento'!B7 -> Design | B8: =C18 -> 5.4868054 | C8: ='Mapas de posicionamento'!C7 -> 2 | D8: ='Mapas de posicionamento'!D7 -> 7 | E8: ='Mapas de posicionamento'!E7 -> 7 | F8: ='Mapas de posicionamento'!F7 -> 7 | G8: ='Mapas de posicionamento'!G7 -> 7 | H8: =B8+(B8-C8) -> 8.9736109 | I8: =$B8+($B8-D8) -> 3.9736109 | J8: =$B8+($B8-E8) -> 3.9736109 | K8: =$B8+($B8-F8) -> 3.9736109 | L8: =$B8+($B8-G8) -> 3.9736109
A9: ='Mapas de posicionamento'!B8 -> Garantia | B9: =C19 -> 3.9383231 | C9: ='Mapas de posicionamento'!C8 -> 3 | D9: ='Mapas de posicionamento'!D8 -> 5 | E9: ='Mapas de posicionamento'!E8 -> 3 | F9: ='Mapas de posicionamento'!F8 -> 8 | G9: ='Mapas de posicionamento'!G8 -> 9 | H9: =B9+(B9-C9) -> 4.8766463 | I9: =$B9+($B9-D9) -> 2.8766463 | J9: =$B9+($B9-E9) -> 4.8766463 | K9: =$B9+($B9-F9) -> -0.12335374 | L9: =$B9+($B9-G9) -> -1.1233537
A10: ='Mapas de posicionamento'!B9 -> Peso | B10: =C20 -> 1.5346398 | C10: ='Mapas de posicionamento'!C9 -> 4 | D10: ='Mapas de posicionamento'!D9 -> 1 | E10: ='Mapas de posicionamento'!E9 -> 2 | F10: ='Mapas de posicionamento'!F9 -> 6 | G10: ='Mapas de posicionamento'!G9 -> 4 | H10: =B10+(B10-C10) -> -0.93072046 | I10: =$B10+($B10-D10) -> 2.0692795 | J10: =$B10+($B10-E10) -> 1.0692795 | K10: =$B10+($B10-F10) -> -2.9307205 | L10: =$B10+($B10-G10) -> -0.93072046
B12: =MAX(B14:B20) -> 0.28572778
A13: Item a ser avaliado | B13: ='calc Hier'!J10 -> Peso do critério | C13: Importância (norm em 9)
A14: =A4 -> Preço | B14: ='calc Hier'!J11 -> 0.28572778 | C14: =B14/MAX($B$14:$B$20)*9 -> 9
A15: =A5 -> Durabilidade | B15: ='calc Hier'!J12 -> 0.12564802 | C15: =B15/MAX($B$14:$B$20)*9 -> 3.9577257
A16: =A6 -> Cor | B16: ='calc Hier'!J13 -> 0.08034649 | C16: =B16/MAX($B$14:$B$20)*9 -> 2.5307949
A17: =A7 -> Acabamento | B17: ='calc Hier'!J14 -> 0.16033213 | C17: =B17/MAX($B$14:$B$20)*9 -> 5.0502237
A18: =A8 -> Design | B18: ='calc Hier'!J15 -> 0.17419252 | C18: =B18/MAX($B$14:$B$20)*9 -> 5.4868054
A19: =A9 -> Garantia | B19: ='calc Hier'!J16 -> 0.12503203 | C19: =B19/MAX($B$14:$B$20)*9 -> 3.9383231
A20: =A10 -> Peso | B20: ='calc Hier'!J17 -> 0.048721023 | C20: =B20/MAX($B$14:$B$20)*9 -> 1.5346398

Sheet Kano
B4: =Radar!A13 -> Item a ser avaliado | C4: =Radar!C13 -> Importância (norm em 9)
B5: =Radar!A20 -> Peso | C5: =Radar!C20 -> 1.5346398
B6: =Radar!A16 -> Cor | C6: =Radar!C16 -> 2.5307949
B7: =Radar!A19 -> Garantia | C7: =Radar!C19 -> 3.9383231
B8: =Radar!A15 -> Durabilidade | C8: =Radar!C15 -> 3.9577257
B9: =Radar!A17 -> Acabamento | C9: =Radar!C17 -> 5.0502237
B10: =Radar!A18 -> Design | C10: =Radar!C18 -> 5.4868054
B11: =Radar!A14 -> Preço | C11: =Radar!C14 -> 9

Sheet Planilha do artigo
A1: CRITÉRIOS | B1: Formação Profissional | C1: Nível de experiência | D1: Capacidade de trabalhar em equipe | E1: Perfil de liderança | F1: SOMA
A2: Formação Profissional | B2: 1 | C2: 3 | D2: 1 | E2: 0.2 | F2: =SUM(B2:E2) -> 5.2
A3: Nível de experiência | B3: 0.33333333 | C3: 1 | D3: 5 | E3: 3 | F3: =SUM(B3:E3) -> 9.3333333
A4: Capacidade de trabalhar em equipe | B4: 1 | C4: 0.2 | D4: 1 | E4: 3 | F4: =SUM(B4:E4) -> 5.2
A5: Perfil de liderança | B5: 5 | C5: 0.33333333 | D5: 0.33333333 | E5: 1 | F5: =SUM(B5:E5) -> 6.6666667
B7: Formação Profissional | C7: Nível de experiência | D7: Capacidade de trabalhar em equipe | E7: Perfil de liderança | F7: SOMA
A8: Candidato A | B8: 3 X (5,20) | C8: 2 X (9,33) | D8: 1 X (5,20) | E8: 1 X (6,67) | F8: 46.133333
A9: Candidato B | B9: 4 X (5,20) | C9: 3 X (9,33) | D9: 4 X (5,20) | E9: 5 X (6,67) | F9: 102.93333
A10: Candidato C | B10: 5 X (5,20) | C10: 5 X (9,33) | D10: 1 X (5,20) | E10: 2 X (6,67) | F10: 91.2
B12: Formação Profissional | C12: Nível de experiência | D12: Capacidade de trabalhar em equipe | E12: Perfil de liderança
A13: Candidato A | B13: 3 | C13: 2 | D13: 1 | E13: 1
A14: Candidato B | B14: 4 | C14: 3 | D14: 4 | E14: 5
A15: Candidato C | B15: 5 | C15: 5 | D15: 1 | E15: 2
A18: Candidato A | B18: =B13*$F$2 -> 15.6 | C18: =C13*$F$3 -> 18.666667 | D18: =D13*$F$4 -> 5.2 | E18: =E13*$F$5 -> 6.6666667 | F18: =SUM(B18:E18) -> 46.133333
A19: Candidato B | B19: =B14*$F$2 -> 20.8 | C19: =C14*$F$3 -> 28 | D19: =D14*$F$4 -> 20.8 | E19: =E14*$F$5 -> 33.333333 | F19: =SUM(B19:E19) -> 102.93333
A20: Candidato C | B20: =B15*$F$2 -> 26 | C20: =C15*$F$3 -> 46.666667 | D20: =D15*$F$4 -> 5.2 | E20: =E15*$F$5 -> 13.333333 | F20: =SUM(B20:E20) -> 91.2
